Traceback (most recent call last):
  File "/home/alexandro/anaconda3/lib/python3.9/site-packages/jupyter_cache/executors/utils.py", line 58, in single_nb_execution
    executenb(
  File "/home/alexandro/anaconda3/lib/python3.9/site-packages/nbclient/client.py", line 1204, in execute
    return NotebookClient(nb=nb, resources=resources, km=km, **kwargs).execute()
  File "/home/alexandro/anaconda3/lib/python3.9/site-packages/nbclient/util.py", line 84, in wrapped
    return just_run(coro(*args, **kwargs))
  File "/home/alexandro/anaconda3/lib/python3.9/site-packages/nbclient/util.py", line 62, in just_run
    return loop.run_until_complete(coro)
  File "/home/alexandro/anaconda3/lib/python3.9/asyncio/base_events.py", line 647, in run_until_complete
    return future.result()
  File "/home/alexandro/anaconda3/lib/python3.9/site-packages/nbclient/client.py", line 663, in async_execute
    await self.async_execute_cell(
  File "/home/alexandro/anaconda3/lib/python3.9/site-packages/nbclient/client.py", line 965, in async_execute_cell
    await self._check_raise_for_error(cell, cell_index, exec_reply)
  File "/home/alexandro/anaconda3/lib/python3.9/site-packages/nbclient/client.py", line 862, in _check_raise_for_error
    raise CellExecutionError.from_cell_and_msg(cell, exec_reply_content)
nbclient.exceptions.CellExecutionError: An error occurred while executing the following cell:
------------------
import fiona
with fiona.open('~/geopythonbook/content/4_br_uf/BR_UF.shp', 'r') as registro:
    print(registro.schema['geometry'])

    for entidade in registro:
        geom = entidade['geometry']  
        props = entidade['properties'] 
        
        # Extrai os atributos desejados
        id_estado = props['CD_UF']
        nome = props['NM_UF']
        sigla = props['SIGLA_UF']
            
        # Imprime os atributos
        print(f'ID: {id_estado}, Nome: {nome}, Sigla: {sigla}')
------------------

[0;31m---------------------------------------------------------------------------[0m
[0;31mCPLE_OpenFailedError[0m                      Traceback (most recent call last)
[0;32mfiona/ogrext.pyx[0m in [0;36mfiona.ogrext.gdal_open_vector[0;34m()[0m

[0;32mfiona/_err.pyx[0m in [0;36mfiona._err.exc_wrap_pointer[0;34m()[0m

[0;31mCPLE_OpenFailedError[0m: ~/geopythonbook/content/4_br_uf/BR_UF.shp: No such file or directory

During handling of the above exception, another exception occurred:

[0;31mDriverError[0m                               Traceback (most recent call last)
[0;32m/tmp/ipykernel_6683/1077616184.py[0m in [0;36m<module>[0;34m[0m
[1;32m      1[0m [0;32mimport[0m [0mfiona[0m[0;34m[0m[0;34m[0m[0m
[0;32m----> 2[0;31m [0;32mwith[0m [0mfiona[0m[0;34m.[0m[0mopen[0m[0;34m([0m[0;34m'~/geopythonbook/content/4_br_uf/BR_UF.shp'[0m[0;34m,[0m [0;34m'r'[0m[0;34m)[0m [0;32mas[0m [0mregistro[0m[0;34m:[0m[0;34m[0m[0;34m[0m[0m
[0m[1;32m      3[0m     [0mprint[0m[0;34m([0m[0mregistro[0m[0;34m.[0m[0mschema[0m[0;34m[[0m[0;34m'geometry'[0m[0;34m][0m[0;34m)[0m[0;34m[0m[0;34m[0m[0m
[1;32m      4[0m [0;34m[0m[0m
[1;32m      5[0m     [0;32mfor[0m [0mentidade[0m [0;32min[0m [0mregistro[0m[0;34m:[0m[0;34m[0m[0;34m[0m[0m

[0;32m~/anaconda3/lib/python3.9/site-packages/fiona/env.py[0m in [0;36mwrapper[0;34m(*args, **kwds)[0m
[1;32m    455[0m [0;34m[0m[0m
[1;32m    456[0m         [0;32mwith[0m [0menv_ctor[0m[0;34m([0m[0msession[0m[0;34m=[0m[0msession[0m[0;34m)[0m[0;34m:[0m[0;34m[0m[0;34m[0m[0m
[0;32m--> 457[0;31m             [0;32mreturn[0m [0mf[0m[0;34m([0m[0;34m*[0m[0margs[0m[0;34m,[0m [0;34m**[0m[0mkwds[0m[0;34m)[0m[0;34m[0m[0;34m[0m[0m
[0m[1;32m    458[0m [0;34m[0m[0m
[1;32m    459[0m     [0;32mreturn[0m [0mwrapper[0m[0;34m[0m[0;34m[0m[0m

[0;32m~/anaconda3/lib/python3.9/site-packages/fiona/__init__.py[0m in [0;36mopen[0;34m(fp, mode, driver, schema, crs, encoding, layer, vfs, enabled_drivers, crs_wkt, allow_unsupported_drivers, **kwargs)[0m
[1;32m    290[0m [0;34m[0m[0m
[1;32m    291[0m         [0;32mif[0m [0mmode[0m [0;32min[0m [0;34m([0m[0;34m"a"[0m[0;34m,[0m [0;34m"r"[0m[0;34m)[0m[0;34m:[0m[0;34m[0m[0;34m[0m[0m
[0;32m--> 292[0;31m             colxn = Collection(
[0m[1;32m    293[0m                 [0mpath[0m[0;34m,[0m[0;34m[0m[0;34m[0m[0m
[1;32m    294[0m                 [0mmode[0m[0;34m,[0m[0;34m[0m[0;34m[0m[0m

[0;32m~/anaconda3/lib/python3.9/site-packages/fiona/collection.py[0m in [0;36m__init__[0;34m(self, path, mode, driver, schema, crs, encoding, layer, vsi, archive, enabled_drivers, crs_wkt, ignore_fields, ignore_geometry, include_fields, wkt_version, allow_unsupported_drivers, **kwargs)[0m
[1;32m    241[0m             [0;32mif[0m [0mself[0m[0;34m.[0m[0mmode[0m [0;34m==[0m [0;34m"r"[0m[0;34m:[0m[0;34m[0m[0;34m[0m[0m
[1;32m    242[0m                 [0mself[0m[0;34m.[0m[0msession[0m [0;34m=[0m [0mSession[0m[0;34m([0m[0;34m)[0m[0;34m[0m[0;34m[0m[0m
[0;32m--> 243[0;31m                 [0mself[0m[0;34m.[0m[0msession[0m[0;34m.[0m[0mstart[0m[0;34m([0m[0mself[0m[0;34m,[0m [0;34m**[0m[0mkwargs[0m[0;34m)[0m[0;34m[0m[0;34m[0m[0m
[0m[1;32m    244[0m             [0;32melif[0m [0mself[0m[0;34m.[0m[0mmode[0m [0;32min[0m [0;34m([0m[0;34m"a"[0m[0;34m,[0m [0;34m"w"[0m[0;34m)[0m[0;34m:[0m[0;34m[0m[0;34m[0m[0m
[1;32m    245[0m                 [0mself[0m[0;34m.[0m[0msession[0m [0;34m=[0m [0mWritingSession[0m[0;34m([0m[0;34m)[0m[0;34m[0m[0;34m[0m[0m

[0;32mfiona/ogrext.pyx[0m in [0;36mfiona.ogrext.Session.start[0;34m()[0m

[0;32mfiona/ogrext.pyx[0m in [0;36mfiona.ogrext.gdal_open_vector[0;34m()[0m

[0;31mDriverError[0m: ~/geopythonbook/content/4_br_uf/BR_UF.shp: No such file or directory
DriverError: ~/geopythonbook/content/4_br_uf/BR_UF.shp: No such file or directory

